Workbook
Name Slicer_CHARGES: #N/A
Name Slicer_DIABETES_STATUS: #N/A
Name Slicer_SMOKER: #N/A
Name Slicer_WEIGHT_STATUS: #N/A

Sheet RD of Customer name
A1: Customer ID | B1: name
A2: Id1 | B2: Hawks, Ms. Kelly
A3: Id2 | B3: Lehner, Mr. Matthew D
A4: Id3 | B4: Lu, Mr. Phil
A5: Id4 | B5: Osborne, Ms. Kelsey
A6: Id5 | B6: Kadala, Ms. Kristyn
A7: Id6 | B7: Baker, Mr. Russell B.
A8: Id7 | B8: Macpherson, Mr. Scott
A9: Id8 | B9: Hallman, Mr. Stephen
A10: Id9 | B10: Moran, Mr. Patrick R.
A11: Id10 | B11: Benner, Ms. Brooke N.
A12: Id11 | B12: Fierro Vargas, Ms. Paola Andrea
... A2336: Id2335 | B2336: German, Mr. Aaron K

Sheet RD of Medical Examine
A1: Customer ID | B1: BMI | C1: HBA1C | D1: Heart Issues | E1: Any Transplants | F1: Cancer history | G1: NumberOfMajorSurgeries | H1: smoker
A2: Id1 | B2: 47.41 | C2: 7.47 | D2: No | E2: No | F2: No | G2: No major surgery | H2: yes
A3: Id2 | B3: 30.36 | C3: 5.77 | D3: No | E3: No | F3: No | G3: No major surgery | H3: yes
A4: Id3 | B4: 34.485 | C4: 11.87 | D4: yes | E4: No | F4: No | G4: 2 | H4: yes
A5: Id4 | B5: 38.095 | C5: 6.05 | D5: No | E5: No | F5: No | G5: No major surgery | H5: yes
A6: Id5 | B6: 35.53 | C6: 5.45 | D6: No | E6: No | F6: No | G6: No major surgery | H6: yes
A7: Id6 | B7: 32.8 | C7: 6.59 | D7: No | E7: No | F7: No | G7: No major surgery | H7: yes
A8: Id7 | B8: 36.4 | C8: 6.07 | D8: No | E8: No | F8: No | G8: No major surgery | H8: yes
A9: Id8 | B9: 36.96 | C9: 7.93 | D9: No | E9: No | F9: No | G9: 3 | H9: yes
A10: Id9 | B10: 41.14 | C10: 9.58 | D10: yes | E10: No | F10: Yes | G10: 1 | H10: yes
A11: Id10 | B11: 38.06 | C11: 10.79 | D11: No | E11: No | F11: No | G11: No major surgery | H11: yes
A12: Id11 | B12: 37.7 | C12: 5.96 | D12: yes | E12: No | F12: No | G12: 2 | H12: yes
A13: Id12 | B13: 42.13 | C13: 11.9 | D13: No | E13: No | F13: No | G13: No major surgery | H13: yes
A14: Id13 | B14: 40.92 | C14: 8.41 | D14: No | E14: No | F14: No | G14: No major surgery | H14: yes
A15: Id14 | B15: 40.565 | C15: 7.02 | D15: No | E15: No | F15: No | G15: No major surgery | H15: yes
A16: Id15 | B16: 36.385 | C16: 7.59 | D16: yes | E16: No | F16: No | G16: 2 | H16: yes
A17: Id16 | B17: 39.9 | C17: 11.32 | D17: No | E17: No | F17: No | G17: No major surgery | H17: yes
A18: Id17 | B18: 33.8 | C18: 7.67 | D18: No | E18: No | F18: No | G18: 3 | H18: yes
A19: Id18 | B19: 36.765 | C19: 7.29 | D19: yes | E19: No | F19: Yes | G19: 1 | H19: yes
A20: Id19 | B20: 36.955 | C20: 4.72 | D20: yes | E20: No | F20: No | G20: 1 | H20: yes
A21: Id20 | B21: 42.9 | C21: 11.41 | D21: No | E21: No | F21: No | G21: No major surgery | H21: yes
A22: Id21 | B22: 36.3 | C22: 11.5 | D22: yes | E22: No | F22: No | G22: 2 | H22: yes
A23: Id22 | B23: 32.2 | C23: 6.22 | D23: yes | E23: No | F23: No | G23: 2 | H23: yes
A24: Id23 | B24: 31.3 | C24: 11.38 | D24: No | E24: No | F24: No | G24: 3 | H24: yes
A25: Id24 | B25: 41.8 | C25: 7.89 | D25: yes | E25: No | F25: No | G25: 2 | H25: yes
A26: Id25 | B26: 35.09 | C26: 4.38 | D26: yes | E26: No | F26: No | G26: 2 | H26: yes
A27: Id26 | B27: 33.88 | C27: 7.01 | D27: No | E27: No | F27: No | G27: 3 | H27: yes
A28: Id27 | B28: 30.875 | C28: 11.88 | D28: No | E28: No | F28: No | G28: No major surgery | H28: yes
A29: Id28 | B29: 36.86 | C29: 5.19 | D29: yes | E29: No | F29: Yes | G29: 1 | H29: yes
A30: Id29 | B30: 35.86 | C30: 6.74 | D30: yes | E30: No | F30: No | G30: 2 | H30: yes
A31: Id30 | B31: 37.05 | C31: 8.44 | D31: No | E31: No | F31: No | G31: No major surgery | H31: yes
A32: Id31 | B32: 43.89 | C32: 8.71 | D32: No | E32: No | F32: No | G32: No major surgery | H32: yes
A33: Id32 | B33: 42.35 | C33: 5.08 | D33: yes | E33: No | F33: No | G33: No major surgery | H33: yes
A34: Id33 | B34: 31.35 | C34: 6.86 | D34: No | E34: No | F34: No | G34: No major surgery | H34: yes
A35: Id34 | B35: 47.6 | C35: 5.95 | D35: yes | E35: No | F35: No | G35: No major surgery | H35: yes
A36: Id35 | B36: 46.2 | C36: 6.09 | D36: No | E36: No | F36: Yes | G36: 1 | H36: yes
A37: Id36 | B37: 32.015 | C37: 11.75 | D37: No | E37: No | F37: No | G37: No major surgery | H37: yes
A38: Id37 | B38: 40.565 | C38: 7.37 | D38: No | E38: No | F38: No | G38: No major surgery | H38: yes
A39: Id38 | B39: 32.45 | C39: 11.91 | D39: No | E39: No | F39: No | G39: No major surgery | H39: yes
A40: Id39 | B40: 34.96 | C40: 6.52 | D40: No | E40: No | F40: No | G40: No major surgery | H40: yes
...

Sheet RD of Hospitalisation Details
A1: Customer ID | B1: year | C1: month | D1: date | E1: children | F1: charges | G1: Hospital tier | H1: City tier | I1: State ID
A2: Id1 | B2: 1968 | C2: Oct | D2: 12 | E2: 0 | F2: 63770.43 | G2: tier - 1 | H2: tier - 3 | I2: R1013 | J2: =VALUE(SUBSTITUTE(A2,"Id","")) -> 1
A3: Id2 | B3: 1977 | C3: Jun | D3: 8 | E3: 0 | F3: 62592.87 | G3: tier - 2 | H3: tier - 3 | I3: R1013 | J3: =VALUE(SUBSTITUTE(A3,"Id","")) -> 2
A4: Id3 | B4: 1970 | C4: ? | D4: 11 | E4: 3 | F4: 60021.4 | G4: tier - 1 | H4: tier - 1 | I4: R1012 | J4: =VALUE(SUBSTITUTE(A4,"Id","")) -> 3
A5: Id4 | B5: 1991 | C5: Jun | D5: 6 | E5: 1 | F5: 58571.07 | G5: tier - 1 | H5: tier - 3 | I5: R1024 | J5: =VALUE(SUBSTITUTE(A5,"Id","")) -> 4
A6: Id5 | B6: 1989 | C6: Jun | D6: 19 | E6: 0 | F6: 55135.4 | G6: tier - 1 | H6: tier - 2 | I6: R1012 | J6: =VALUE(SUBSTITUTE(A6,"Id","")) -> 5
A7: Id6 | B7: 1962 | C7: Aug | D7: 4 | E7: 0 | F7: 52590.83 | G7: tier - 1 | H7: tier - 3 | I7: R1011 | J7: =VALUE(SUBSTITUTE(A7,"Id","")) -> 6
A8: Id7 | B8: 1994 | C8: Oct | D8: 27 | E8: 1 | F8: 51194.56 | G8: tier - 1 | H8: tier - 3 | I8: R1011 | J8: =VALUE(SUBSTITUTE(A8,"Id","")) -> 7
A9: Id8 | B9: 1958 | C9: Jun | D9: 27 | E9: 2 | F9: 49577.66 | G9: tier - 2 | H9: tier - 2 | I9: R1013 | J9: =VALUE(SUBSTITUTE(A9,"Id","")) -> 8
A10: Id9 | B10: 1963 | C10: Sep | D10: 4 | E10: 1 | F10: 48970.25 | G10: tier - 1 | H10: tier - 2 | I10: R1013 | J10: =VALUE(SUBSTITUTE(A10,"Id","")) -> 9
A11: Id10 | B11: 1978 | C11: Dec | D11: 29 | E11: 0 | F11: 48885.14 | G11: tier - 1 | H11: tier - 2 | I11: R1013 | J11: =VALUE(SUBSTITUTE(A11,"Id","")) -> 10
A12: Id11 | B12: 1959 | C12: Jul | D12: 22 | E12: 0 | F12: 48824.45 | G12: tier - 2 | H12: tier - 1 | I12: R1011 | J12: =VALUE(SUBSTITUTE(A12,"Id","")) -> 11
A13: Id12 | B13: 1965 | C13: Oct | D13: 27 | E13: 1 | F13: 48675.52 | G13: tier - 1 | H13: tier - 2 | I13: R1013 | J13: =VALUE(SUBSTITUTE(A13,"Id","")) -> 12
... A1286: Id1285 | B1286: 1975 | C1286: Aug | D1286: 6 | E1286: 1 | F1286: 8551.35 | G1286: tier - 2 | H1286: tier - 2 | I1286: R1011 | J1286: =VALUE(SUBSTITUTE(A1286,"Id","")) -> 1285
A1287: Id1286 | B1287: ? | C1287: Dec | D1287: 12 | E1287: 1 | F1287: 8547.69 | G1287: tier - 2 | H1287: tier - 1 | I1287: R1013 | J1287: =VALUE(SUBSTITUTE(A1287,"Id","")) -> 1286
A1288: Id1287 | B1288: 1975 | C1288: Nov | D1288: 6 | E1288: 1 | F1288: 8539.67 | G1288: tier - 2 | H1288: tier - 3 | I1288: R1011 | J1288: =VALUE(SUBSTITUTE(A1288,"Id","")) -> 1287
A1289: Id1288 | B1289: 1981 | C1289: Dec | D1289: 27 | E1289: 3 | F1289: 8538.29 | G1289: tier - 2 | H1289: tier - 3 | I1289: R1024 | J1289: =VALUE(SUBSTITUTE(A1289,"Id","")) -> 1288
A1290: Id1289 | B1290: ? | C1290: Jul | D1290: 24 | E1290: 0 | F1290: 8534.67 | G1290: tier - 2 | H1290: tier - 3 | I1290: R1024 | J1290: =VALUE(SUBSTITUTE(A1290,"Id","")) -> 1289
A1291: Id1290 | B1291: 1977 | C1291: Jul | D1291: 26 | E1291: 2 | F1291: 8527.53 | G1291: tier - 2 | H1291: tier - 2 | I1291: R1013 | J1291: =VALUE(SUBSTITUTE(A1291,"Id","")) -> 1290
A1292: Id1291 | B1292: 1979 | C1292: Aug | D1292: 13 | E1292: 3 | F1292: 8522 | G1292: tier - 2 | H1292: tier - 2 | I1292: R1011 | J1292: =VALUE(SUBSTITUTE(A1292,"Id","")) -> 1291
A1293: Id1292 | B1293: 1977 | C1293: Dec | D1293: 29 | E1293: 2 | F1293: 8520.03 | G1293: tier - 2 | H1293: tier - 3 | I1293: R1011 | J1293: =VALUE(SUBSTITUTE(A1293,"Id","")) -> 1292
A1294: Id1293 | B1294: 1977 | C1294: Jun | D1294: 21 | E1294: 2 | F1294: 8516.83 | G1294: tier - 2 | H1294: tier - 1 | I1294: R1013 | J1294: =VALUE(SUBSTITUTE(A1294,"Id","")) -> 1293
A1295: Id1294 | B1295: 1977 | C1295: Dec | D1295: 26 | E1295: 2 | F1295: 8515.76 | G1295: tier - 2 | H1295: tier - 2 | I1295: R1013 | J1295: =VALUE(SUBSTITUTE(A1295,"Id","")) -> 1294
A1296: Id1295 | B1296: 1993 | C1296: Nov | D1296: 10 | E1296: 0 | F1296: 8471.65 | G1296: tier - 2 | H1296: tier - 1 | I1296: R1012 | J1296: =VALUE(SUBSTITUTE(A1296,"Id","")) -> 1295
A1297: Id1296 | B1297: 1992 | C1297: Sep | D1297: 9 | E1297: 0 | F1297: 8466.35 | G1297: tier - 2 | H1297: tier - 2 | I1297: R1012 | J1297: =VALUE(SUBSTITUTE(A1297,"Id","")) -> 1296
A1298: Id1297 | B1298: 1972 | C1298: Dec | D1298: 26 | E1298: 0 | F1298: 8457.82 | G1298: tier - 2 | H1298: tier - 3 | I1298: R1011 | J1298: =VALUE(SUBSTITUTE(A1298,"Id","")) -> 1297
A1299: Id1298 | B1299: 1984 | C1299: Jun | D1299: 19 | E1299: 3 | F1299: 8450.82 | G1299: tier - 2 | H1299: tier - 2 | I1299: R1025 | J1299: =VALUE(SUBSTITUTE(A1299,"Id","")) -> 1298
A1300: Id1299 | B1300: 1966 | C1300: Jun | D1300: 12 | E1300: 0 | F1300: 8448.66 | G1300: tier - 3 | H1300: tier - 1 | I1300: R1013 | J1300: =VALUE(SUBSTITUTE(A1300,"Id","")) -> 1299
A1301: Id1300 | B1301: 1972 | C1301: Sep | D1301: 4 | E1301: 0 | F1301: 8444.47 | G1301: tier - 3 | H1301: tier - 1 | I1301: R1011 | J1301: =VALUE(SUBSTITUTE(A1301,"Id","")) -> 1300
A1302: Id1301 | B1302: 1972 | C1302: Sep | D1302: 9 | E1302: 0 | F1302: 8442.67 | G1302: tier - 2 | H1302: tier - 3 | I1302: R1013 | J1302: =VALUE(SUBSTITUTE(A1302,"Id","")) -> 1301
... A2344: ? | B2344: 1991 | C2344: Nov | D2344: 22 | E2344: 2 | F2344: 38711 | G2344: tier - 1 | H2344: tier - 3 | I2344: R1011 | J2344: =VALUE(SUBSTITUTE(A2344,"Id","")) -> #VALUE!

Sheet Customer Names
A1: CUSTOMER ID | B1: TITLE | C1: FIRST NAME | D1: LAST NAME
A2: ID-1 | B2: Ms. | C2: Kelly | D2: Hawks | H2: • I have splited the name column into 3 column as TITLE, FIRST NAME, LAST NAME
A3: ID-2 | B3: Mr. | C3: Matthew D | D3: Lehner
A4: ID-3 | B4: Mr. | C4: Phil | D4: Lu | H4: • At first step, i use SPLIT TEXT TO COLUMNS tool to split, i can extract only the last name. Again i used the functions like TEXT BEFORE and TEXT AFTER to split the TITLE and FIRST NAME
A5: ID-4 | B5: Ms. | C5: Kelsey | D5: Osborne
A6: ID-5 | B6: Ms. | C6: Kristyn | D6: Kadala
A7: ID-6 | B7: Mr. | C7: Russell B. | D7: Baker
A8: ID-7 | B8: Mr. | C8: Scott | D8: Macpherson | H8: UPPER(LEFT(A2,2))&"-"&RIGHT(A2,LEN(A2)-2)
A9: ID-8 | B9: Mr. | C9: Stephen | D9: Hallman | H9: • I Used this function to make inconsistent IDs into proper ID look.
A10: ID-9 | B10: Mr. | C10: Patrick R. | D10: Moran
A11: ID-10 | B11: Ms. | C11: Brooke N. | D11: Benner
A12: ID-11 | B12: Ms. | C12: Paola Andrea | D12: Fierro Vargas
A13: ID-12 | B13: Mr. | C13: David | D13: Franz
A14: ID-13 | B14: Mr. | C14: Wade | D14: Foster
A15: ID-14 | B15: Mr. | C15: Franklin | D15: Tenorio
A16: ID-15 | B16: Ms. | C16: Leilani M. | D16: Rios
A17: ID-16 | B17: Mr. | C17: Philippe | D17: Viau-Dupuis
A18: ID-17 | B18: Ms. | C18: Jennifer A. | D18: Cronin
A19: ID-18 | B19: Ms. | C19: Christina M. | D19: Noordstar
A20: ID-19 | B20: Mr. | C20: Said Sr. | D20: Boudalia
A21: ID-20 | B21: Mr. | C21: John | D21: Flor
... A2336: ID-2335 | B2336: Mr. | C2336: Aaron K | D2336: German

Sheet Medical Examine
A1: CUSTOMER ID | B1: BMI | C1: WEIGHT STATUS | D1: HBA1C | E1: HEART ISSUES | F1: ANY TRANSPLANTS | G1: CANCER HISTORY | H1: NO. OF MAJOR SURGERIES | I1: SMOKER
A2: ID-1 | B2: 47.41 | C2: =IF(B2<18.5,"Under Weight",IF(B2<25,"Normal Weight",IF(B2<30,"Overweight","Obesity"))) -> Obesity | D2: 7.47 | E2: NO | F2: NO | G2: NO | H2: 0 | I2: YES
A3: ID-2 | B3: 30.36 | C3: =IF(B3<18.5,"Under Weight",IF(B3<25,"Normal Weight",IF(B3<30,"Overweight","Obesity"))) -> Obesity | D3: 5.77 | E3: NO | F3: NO | G3: NO | H3: 0 | I3: YES
A4: ID-3 | B4: 34.485 | C4: =IF(B4<18.5,"Under Weight",IF(B4<25,"Normal Weight",IF(B4<30,"Overweight","Obesity"))) -> Obesity | D4: 11.87 | E4: YES | F4: NO | G4: NO | H4: 2 | I4: YES | L4: • The missing Value in the Smoker column were replaced with the mode, which is "No", as it is the most frequently occuring value.
A5: ID-4 | B5: 38.095 | C5: =IF(B5<18.5,"Under Weight",IF(B5<25,"Normal Weight",IF(B5<30,"Overweight","Obesity"))) -> Obesity | D5: 6.05 | E5: NO | F5: NO | G5: NO | H5: 0 | I5: YES
A6: ID-5 | B6: 35.53 | C6: =IF(B6<18.5,"Under Weight",IF(B6<25,"Normal Weight",IF(B6<30,"Overweight","Obesity"))) -> Obesity | D6: 5.45 | E6: NO | F6: NO | G6: NO | H6: 0 | I6: YES
A7: ID-6 | B7: 32.8 | C7: =IF(B7<18.5,"Under Weight",IF(B7<25,"Normal Weight",IF(B7<30,"Overweight","Obesity"))) -> Obesity | D7: 6.59 | E7: NO | F7: NO | G7: NO | H7: 0 | I7: YES | L7: • Weight Column is a column was created to determine the weight category according to the BMI values.
A8: ID-7 | B8: 36.4 | C8: =IF(B8<18.5,"Under Weight",IF(B8<25,"Normal Weight",IF(B8<30,"Overweight","Obesity"))) -> Obesity | D8: 6.07 | E8: NO | F8: NO | G8: NO | H8: 0 | I8: YES | Q8: IF(B<18.5,"Underweight",IF(B<25,"Normal weight",IF(B<30,"Overweight","Obesity")))
A9: ID-8 | B9: 36.96 | C9: =IF(B9<18.5,"Under Weight",IF(B9<25,"Normal Weight",IF(B9<30,"Overweight","Obesity"))) -> Obesity | D9: 7.93 | E9: NO | F9: NO | G9: NO | H9: 3 | I9: YES
A10: ID-9 | B10: 41.14 | C10: =IF(B10<18.5,"Under Weight",IF(B10<25,"Normal Weight",IF(B10<30,"Overweight","Obesity"))) -> Obesity | D10: 9.58 | E10: YES | F10: NO | G10: YES | H10: 1 | I10: YES | L10: • In 'Number of Major Surgeries' Column, where non-numeric characters were converted into meaningful Numeric values.
A11: ID-10 | B11: 38.06 | C11: =IF(B11<18.5,"Under Weight",IF(B11<25,"Normal Weight",IF(B11<30,"Overweight","Obesity"))) -> Obesity | D11: 10.79 | E11: NO | F11: NO | G11: NO | H11: 0 | I11: YES
A12: ID-11 | B12: 37.7 | C12: =IF(B12<18.5,"Under Weight",IF(B12<25,"Normal Weight",IF(B12<30,"Overweight","Obesity"))) -> Obesity | D12: 5.96 | E12: YES | F12: NO | G12: NO | H12: 2 | I12: YES
A13: ID-12 | B13: 42.13 | C13: =IF(B13<18.5,"Under Weight",IF(B13<25,"Normal Weight",IF(B13<30,"Overweight","Obesity"))) -> Obesity | D13: 11.9 | E13: NO | F13: NO | G13: NO | H13: 0 | I13: YES | L13: • The Columns 'Heart Issues' and 'Smoker' were changed from inconsistencies into Proper case.
A14: ID-13 | B14: 40.92 | C14: =IF(B14<18.5,"Under Weight",IF(B14<25,"Normal Weight",IF(B14<30,"Overweight","Obesity"))) -> Obesity | D14: 8.41 | E14: NO | F14: NO | G14: NO | H14: 0 | I14: YES
A15: ID-14 | B15: 40.565 | C15: =IF(B15<18.5,"Under Weight",IF(B15<25,"Normal Weight",IF(B15<30,"Overweight","Obesity"))) -> Obesity | D15: 7.02 | E15: NO | F15: NO | G15: NO | H15: 0 | I15: YES
A16: ID-15 | B16: 36.385 | C16: =IF(B16<18.5,"Under Weight",IF(B16<25,"Normal Weight",IF(B16<30,"Overweight","Obesity"))) -> Obesity | D16: 7.59 | E16: YES | F16: NO | G16: NO | H16: 2 | I16: YES
A17: ID-16 | B17: 39.9 | C17: =IF(B17<18.5,"Under Weight",IF(B17<25,"Normal Weight",IF(B17<30,"Overweight","Obesity"))) -> Obesity | D17: 11.32 | E17: NO | F17: NO | G17: NO | H17: 0 | I17: YES
A18: ID-17 | B18: 33.8 | C18: =IF(B18<18.5,"Under Weight",IF(B18<25,"Normal Weight",IF(B18<30,"Overweight","Obesity"))) -> Obesity | D18: 7.67 | E18: NO | F18: NO | G18: NO | H18: 3 | I18: YES
A19: ID-18 | B19: 36.765 | C19: =IF(B19<18.5,"Under Weight",IF(B19<25,"Normal Weight",IF(B19<30,"Overweight","Obesity"))) -> Obesity | D19: 7.29 | E19: YES | F19: NO | G19: YES | H19: 1 | I19: YES
A20: ID-19 | B20: 36.955 | C20: =IF(B20<18.5,"Under Weight",IF(B20<25,"Normal Weight",IF(B20<30,"Overweight","Obesity"))) -> Obesity | D20: 4.72 | E20: YES | F20: NO | G20: NO | H20: 1 | I20: YES
A21: ID-20 | B21: 42.9 | C21: =IF(B21<18.5,"Under Weight",IF(B21<25,"Normal Weight",IF(B21<30,"Overweight","Obesity"))) -> Obesity | D21: 11.41 | E21: NO | F21: NO | G21: NO | H21: 0 | I21: YES
A22: ID-21 | B22: 36.3 | C22: =IF(B22<18.5,"Under Weight",IF(B22<25,"Normal Weight",IF(B22<30,"Overweight","Obesity"))) -> Obesity | D22: 11.5 | E22: YES | F22: NO | G22: NO | H22: 2 | I22: YES
A23: ID-22 | B23: 32.2 | C23: =IF(B23<18.5,"Under Weight",IF(B23<25,"Normal Weight",IF(B23<30,"Overweight","Obesity"))) -> Obesity | D23: 6.22 | E23: YES | F23: NO | G23: NO | H23: 2 | I23: YES
A24: ID-23 | B24: 31.3 | C24: =IF(B24<18.5,"Under Weight",IF(B24<25,"Normal Weight",IF(B24<30,"Overweight","Obesity"))) -> Obesity | D24: 11.38 | E24: NO | F24: NO | G24: NO | H24: 3 | I24: YES
A25: ID-24 | B25: 41.8 | C25: =IF(B25<18.5,"Under Weight",IF(B25<25,"Normal Weight",IF(B25<30,"Overweight","Obesity"))) -> Obesity | D25: 7.89 | E25: YES | F25: NO | G25: NO | H25: 2 | I25: YES
... A2336: ID-2335 | B2336: 17.58 | C2336: =IF(B2336<18.5,"Under Weight",IF(B2336<25,"Normal Weight",IF(B2336<30,"Overweight","Obesity"))) -> Under Weight | D2336: 4.51 | E2336: NO | F2336: NO | G2336: NO | H2336: 1 | I2336: NO

Sheet Hospitalisation Details
A1: CUSTOMER ID | B1: YEAR | C1: MONTH | D1: DATE | E1: DATE OF BIRTH | F1: AGE | G1: CHILDREN | H1: CHARGES | I1: HOSPITAL TIER | J1: CITY TIER | K1: STATE ID
A2: ID-1 | B2: 1968 | C2: Oct | D2: 12 | E2: =DATE(B2,MONTH(DATEVALUE("1-"&C2&"-"&B2)),D2) -> 25123 | F2: =DATEDIF(E2,DATE(2023,6,8),"y") -> 54 | G2: 0 | H2: 63770.43 | I2: tier - 1 | J2: tier - 3 | K2: R1013 | N2: • For missing Values of YEAR [IF(B2="?",ROUND(AVERAGEIF($B$2:$B$2339,"<>?",$B$2:$B$2339),0),B2)] ,which is the function that i used to find out the missing YEAR
A3: ID-2 | B3: 1977 | C3: Jun | D3: 8 | E3: =DATE(B3,MONTH(DATEVALUE("1-"&C3&"-"&B3)),D3) -> 28284 | F3: =DATEDIF(E3,DATE(2023,6,8),"y") -> 46 | G3: 0 | H3: 62592.87 | I3: tier - 2 | J3: tier - 3 | K3: R1013
A4: ID-3 | B4: 1970 | C4: Sep | D4: 11 | E4: =DATE(B4,MONTH(DATEVALUE("1-"&C4&"-"&B4)),D4) -> 25822 | F4: =DATEDIF(E4,DATE(2023,6,8),"y") -> 52 | G4: 3 | H4: 60021.4 | I4: tier - 1 | J4: tier - 1 | K4: R1012
A5: ID-4 | B5: 1991 | C5: Jun | D5: 6 | E5: =DATE(B5,MONTH(DATEVALUE("1-"&C5&"-"&B5)),D5) -> 33395 | F5: =DATEDIF(E5,DATE(2023,6,8),"y") -> 32 | G5: 1 | H5: 58571.07 | I5: tier - 1 | J5: tier - 3 | K5: R1024
A6: ID-5 | B6: 1989 | C6: Jun | D6: 19 | E6: =DATE(B6,MONTH(DATEVALUE("1-"&C6&"-"&B6)),D6) -> 32678 | F6: =DATEDIF(E6,DATE(2023,6,8),"y") -> 33 | G6: 0 | H6: 55135.4 | I6: tier - 1 | J6: tier - 2 | K6: R1012 | N6: • For missing value of Month, as per the instruction, '?' replaced with "Sep".
A7: ID-6 | B7: 1962 | C7: Aug | D7: 4 | E7: =DATE(B7,MONTH(DATEVALUE("1-"&C7&"-"&B7)),D7) -> 22862 | F7: =DATEDIF(E7,DATE(2023,6,8),"y") -> 60 | G7: 0 | H7: 52590.83 | I7: tier - 1 | J7: tier - 3 | K7: R1011
A8: ID-7 | B8: 1994 | C8: Oct | D8: 27 | E8: =DATE(B8,MONTH(DATEVALUE("1-"&C8&"-"&B8)),D8) -> 34634 | F8: =DATEDIF(E8,DATE(2023,6,8),"y") -> 28 | G8: 1 | H8: 51194.56 | I8: tier - 1 | J8: tier - 3 | K8: R1011 | N8: • In 'State ID' cloumn, the missing values are filled with 'Unknown' Category.
A9: ID-8 | B9: 1958 | C9: Jun | D9: 27 | E9: =DATE(B9,MONTH(DATEVALUE("1-"&C9&"-"&B9)),D9) -> 21363 | F9: =DATEDIF(E9,DATE(2023,6,8),"y") -> 64 | G9: 2 | H9: 49577.66 | I9: tier - 2 | J9: tier - 2 | K9: R1013
A10: ID-9 | B10: 1963 | C10: Sep | D10: 4 | E10: =DATE(B10,MONTH(DATEVALUE("1-"&C10&"-"&B10)),D10) -> 23258 | F10: =DATEDIF(E10,DATE(2023,6,8),"y") -> 59 | G10: 1 | H10: 48970.25 | I10: tier - 1 | J10: tier - 2 | K10: R1013 | N10: • The 'Year', 'Month', and 'Date' columns were merged in the name of "Date of Birth" and change the format into 'dd/mm/yyyy'.
A11: ID-10 | B11: 1978 | C11: Dec | D11: 29 | E11: =DATE(B11,MONTH(DATEVALUE("1-"&C11&"-"&B11)),D11) -> 28853 | F11: =DATEDIF(E11,DATE(2023,6,8),"y") -> 44 | G11: 0 | H11: 48885.14 | I11: tier - 1 | J11: tier - 2 | K11: R1013
A12: ID-11 | B12: 1959 | C12: Jul | D12: 22 | E12: =DATE(B12,MONTH(DATEVALUE("1-"&C12&"-"&B12)),D12) -> 21753 | F12: =DATEDIF(E12,DATE(2023,6,8),"y") -> 63 | G12: 0 | H12: 48824.45 | I12: tier - 2 | J12: tier - 1 | K12: R1011 | N12: Date(B,Month(Datevalue("1-"&C&"-"&B)),D)
A13: ID-12 | B13: 1965 | C13: Oct | D13: 27 | E13: =DATE(B13,MONTH(DATEVALUE("1-"&C13&"-"&B13)),D13) -> 24042 | F13: =DATEDIF(E13,DATE(2023,6,8),"y") -> 57 | G13: 1 | H13: 48675.52 | I13: tier - 1 | J13: tier - 2 | K13: R1013 | N13: • For each customer, AGE were calculated based on their 'Date of Birth' and created as a new column.
A14: ID-13 | B14: 1962 | C14: Oct | D14: 11 | E14: =DATE(B14,MONTH(DATEVALUE("1-"&C14&"-"&B14)),D14) -> 22930 | F14: =DATEDIF(E14,DATE(2023,6,8),"y") -> 60 | G14: 0 | H14: 48673.56 | I14: tier - 1 | J14: tier - 2 | K14: R1013
A15: ID-14 | B15: 1968 | C15: Dec | D15: 1 | E15: =DATE(B15,MONTH(DATEVALUE("1-"&C15&"-"&B15)),D15) -> 25173 | F15: =DATEDIF(E15,DATE(2023,6,8),"y") -> 54 | G15: 3 | H15: 48549.18 | I15: tier - 1 | J15: tier - 3 | K15: R1016 | N15: • The 'Charges' column has been format as currency($)
A16: ID-15 | B16: 1961 | C16: Dec | D16: 21 | E16: =DATE(B16,MONTH(DATEVALUE("1-"&C16&"-"&B16)),D16) -> 22636 | F16: =DATEDIF(E16,DATE(2023,6,8),"y") -> 61 | G16: 1 | H16: 48517.56 | I16: tier - 1 | J16: tier - 3 | K16: R1024 | N16: • For the missing Values in 'Hospital tier' and 'City tier' were filled by determined the most repeated values.
A17: ID-16 | B17: 1962 | C17: Aug | D17: 27 | E17: =DATE(B17,MONTH(DATEVALUE("1-"&C17&"-"&B17)),D17) -> 22885 | F17: =DATEDIF(E17,DATE(2023,6,8),"y") -> 60 | G17: 0 | H17: 48173.36 | I17: tier - 1 | J17: tier - 3 | K17: R1011
A18: ID-17 | B18: 1958 | C18: Nov | D18: 16 | E18: =DATE(B18,MONTH(DATEVALUE("1-"&C18&"-"&B18)),D18) -> 21505 | F18: =DATEDIF(E18,DATE(2023,6,8),"y") -> 64 | G18: 1 | H18: 47928.03 | I18: tier - 2 | J18: tier - 3 | K18: R1011
A19: ID-18 | B19: 1963 | C19: Aug | D19: 5 | E19: =DATE(B19,MONTH(DATEVALUE("1-"&C19&"-"&B19)),D19) -> 23228 | F19: =DATEDIF(E19,DATE(2023,6,8),"y") -> 59 | G19: 1 | H19: 47896.79 | I19: tier - 1 | J19: tier - 3 | K19: R1024
A20: ID-19 | B20: 1964 | C20: Nov | D20: 7 | E20: =DATE(B20,MONTH(DATEVALUE("1-"&C20&"-"&B20)),D20) -> 23688 | F20: =DATEDIF(E20,DATE(2023,6,8),"y") -> 58 | G20: 2 | H20: 47496.49 | I20: tier - 1 | J20: tier - 3 | K20: R1012
A21: ID-20 | B21: 1971 | C21: Sep | D21: 27 | E21: =DATE(B21,MONTH(DATEVALUE("1-"&C21&"-"&B21)),D21) -> 26203 | F21: =DATEDIF(E21,DATE(2023,6,8),"y") -> 51 | G21: 2 | H21: 47462.89 | I21: tier - 1 | J21: tier - 2 | K21: R1013
A22: ID-21 | B22: 1961 | C22: Jun | D22: 13 | E22: =DATE(B22,MONTH(DATEVALUE("1-"&C22&"-"&B22)),D22) -> 22445 | F22: =DATEDIF(E22,DATE(2023,6,8),"y") -> 61 | G22: 1 | H22: 47403.88 | I22: tier - 1 | J22: tier - 3 | K22: R1011
A23: ID-22 | B23: 1959 | C23: Oct | D23: 4 | E23: =DATE(B23,MONTH(DATEVALUE("1-"&C23&"-"&B23)),D23) -> 21827 | F23: =DATEDIF(E23,DATE(2023,6,8),"y") -> 63 | G23: 2 | H23: 47305.31 | I23: tier - 2 | J23: tier - 1 | K23: R1011
A24: ID-23 | B24: 1958 | C24: Sep | D24: 3 | E24: =DATE(B24,MONTH(DATEVALUE("1-"&C24&"-"&B24)),D24) -> 21431 | F24: =DATEDIF(E24,DATE(2023,6,8),"y") -> 64 | G24: 2 | H24: 47291.06 | I24: tier - 2 | J24: tier - 1 | K24: R1011
A25: ID-24 | B25: 1970 | C25: Dec | D25: 28 | E25: =DATE(B25,MONTH(DATEVALUE("1-"&C25&"-"&B25)),D25) -> 25930 | F25: =DATEDIF(E25,DATE(2023,6,8),"y") -> 52 | G25: 2 | H25: 47269.85 | I25: tier - 1 | J25: tier - 2 | K25: R1013
A26: ID-25 | B26: 1959 | C26: Jul | D26: 14 | E26: =DATE(B26,MONTH(DATEVALUE("1-"&C26&"-"&B26)),D26) -> 21745 | F26: =DATEDIF(E26,DATE(2023,6,8),"y") -> 63 | G26: 0 | H26: 47055.53 | I26: tier - 2 | J26: tier - 1 | K26: R1013
A27: ID-26 | B27: 1958 | C27: Sep | D27: 15 | E27: =DATE(B27,MONTH(DATEVALUE("1-"&C27&"-"&B27)),D27) -> 21443 | F27: =DATEDIF(E27,DATE(2023,6,8),"y") -> 64 | G27: 0 | H27: 46889.26 | I27: tier - 2 | J27: tier - 3 | K27: R1013
A28: ID-27 | B28: 1960 | C28: Nov | D28: 17 | E28: =DATE(B28,MONTH(DATEVALUE("1-"&C28&"-"&B28)),D28) -> 22237 | F28: =DATEDIF(E28,DATE(2023,6,8),"y") -> 62 | G28: 3 | H28: 46718.16 | I28: tier - 1 | J28: tier - 1 | K28: R1012
... A2339: Unknown | B2339: 2004 | C2339: Nov | D2339: 6 | E2339: =DATE(B2339,MONTH(DATEVALUE("1-"&C2339&"-"&B2339)),D2339) -> 38297 | F2339: =DATEDIF(E2339,DATE(2023,6,8),"y") -> 18 | G2339: 0 | H2339: 1137.01 | I2339: tier - 3 | J2339: tier - 1 | K2339: R1013

Sheet Healthcare
A1: CUSTOMER ID | B1: FIRST NAME | C1: BMI | D1: HbA1C | E1: HEART ISSUES | F1: ANY TRANSPLANTS | G1: CANCER HISTORY | H1: NO. OF MAJOR SURGERIES | I1: SMOKER | J1: WEIGHT STATUS | K1: DIABETES STATUS | L1: DATE OF BIRTH | M1: CHARGES | N1: HOSPITAL TIER | O1: CITY TIER | P1: STATE ID | Q1: AGE
A2: ID-1 | B2: =_xlfn.XLOOKUP(A2,'Customer Names'!$A$2:$A$2336,'Customer Names'!$C$2:$C$2336,"Not Found") -> Kelly | C2: =_xlfn.XLOOKUP(A2,'Medical Examine'!$A$2:$A$2336,'Medical Examine'!$B$2:$B$2336,"Not Found") -> 47.41 | D2: =_xlfn.XLOOKUP(A2,'Medical Examine'!$A$2:$A$2336,'Medical Examine'!$D$2:$D$2336,"Not Found") -> 7.47 | E2: =_xlfn.XLOOKUP(A2,'Medical Examine'!$A$2:$A$2336,'Medical Examine'!$E$2:$E$2336,"Not Found") -> NO | F2: =_xlfn.XLOOKUP(A2,'Medical Examine'!$A$2:$A$2336,'Medical Examine'!$F$2:$F$2336,"Not Found") -> NO | G2: =_xlfn.XLOOKUP(A2,'Medical Examine'!$A$2:$A$2336,'Medical Examine'!$G$2:$G$2336,"Not Found") -> NO | H2: =_xlfn.XLOOKUP(A2,'Medical Examine'!$A$2:$A$2336,'Medical Examine'!$H$2:$H$2336,"Not Found") -> 0 | I2: =_xlfn.XLOOKUP(A2,'Medical Examine'!$A$2:$A$2336,'Medical Examine'!$I$2:$I$2336,"Not Found") -> YES | J2: =_xlfn.XLOOKUP(A2,'Medical Examine'!$A$2:$A$2336,'Medical Examine'!$C$2:$C$2336,"Not Found") -> Obesity | K2: =IF(D2>=6.5,"Diabetic",IF(D2>=5.7,"Prediabetic","Normal")) -> Diabetic | L2: =_xlfn.XLOOKUP(A2,'Hospitalisation Details'!$A$2:$A$2344,'Hospitalisation Details'!$E$2:$E$2344,"") -> 25123 | M2: =_xlfn.XLOOKUP(A2,'Hospitalisation Details'!$A$2:$A$2344,'Hospitalisation Details'!$H$2:$H$2344,"") -> 63770.43 | N2: =_xlfn.XLOOKUP(A2,'Hospitalisation Details'!$A$2:$A$2344,'Hospitalisation Details'!$I$2:$I$2344,"") -> tier - 1 | O2: =_xlfn.XLOOKUP(A2,'Hospitalisation Details'!$A$2:$A$2344,'Hospitalisation Details'!$J$2:$J$2344,"") -> tier - 3 | P2: =_xlfn.XLOOKUP(A2,'Hospitalisation Details'!$A$2:$A$2344,'Hospitalisation Details'!$K$2:$K$2344,"") -> R1013 | Q2: =_xlfn.XLOOKUP(A2,'Hospitalisation Details'!$A$2:$A$2344,'Hospitalisation Details'!$F$2:$F$2344,"") -> 54
A3: ID-2 | B3: =_xlfn.XLOOKUP(A3,'Customer Names'!$A$2:$A$2336,'Customer Names'!$C$2:$C$2336,"Not Found") -> Matthew D | C3: =_xlfn.XLOOKUP(A3,'Medical Examine'!$A$2:$A$2336,'Medical Examine'!$B$2:$B$2336,"Not Found") -> 30.36 | D3: =_xlfn.XLOOKUP(A3,'Medical Examine'!$A$2:$A$2336,'Medical Examine'!$D$2:$D$2336,"Not Found") -> 5.77 | E3: =_xlfn.XLOOKUP(A3,'Medical Examine'!$A$2:$A$2336,'Medical Examine'!$E$2:$E$2336,"Not Found") -> NO | F3: =_xlfn.XLOOKUP(A3,'Medical Examine'!$A$2:$A$2336,'Medical Examine'!$F$2:$F$2336,"Not Found") -> NO | G3: =_xlfn.XLOOKUP(A3,'Medical Examine'!$A$2:$A$2336,'Medical Examine'!$G$2:$G$2336,"Not Found") -> NO | H3: =_xlfn.XLOOKUP(A3,'Medical Examine'!$A$2:$A$2336,'Medical Examine'!$H$2:$H$2336,"Not Found") -> 0 | I3: =_xlfn.XLOOKUP(A3,'Medical Examine'!$A$2:$A$2336,'Medical Examine'!$I$2:$I$2336,"Not Found") -> YES | J3: =_xlfn.XLOOKUP(A3,'Medical Examine'!$A$2:$A$2336,'Medical Examine'!$C$2:$C$2336,"Not Found") -> Obesity | K3: =IF(D3>=6.5,"Diabetic",IF(D3>=5.7,"Prediabetic","Normal")) -> Prediabetic | L3: =_xlfn.XLOOKUP(A3,'Hospitalisation Details'!$A$2:$A$2344,'Hospitalisation Details'!$E$2:$E$2344,"") -> 28284 | M3: =_xlfn.XLOOKUP(A3,'Hospitalisation Details'!$A$2:$A$2344,'Hospitalisation Details'!$H$2:$H$2344,"") -> 62592.87 | N3: =_xlfn.XLOOKUP(A3,'Hospitalisation Details'!$A$2:$A$2344,'Hospitalisation Details'!$I$2:$I$2344,"") -> tier - 2 | O3: =_xlfn.XLOOKUP(A3,'Hospitalisation Details'!$A$2:$A$2344,'Hospitalisation Details'!$J$2:$J$2344,"") -> tier - 3 | P3: =_xlfn.XLOOKUP(A3,'Hospitalisation Details'!$A$2:$A$2344,'Hospitalisation Details'!$K$2:$K$2344,"") -> R1013 | Q3: =_xlfn.XLOOKUP(A3,'Hospitalisation Details'!$A$2:$A$2344,'Hospitalisation Details'!$F$2:$F$2344,"") -> 46
A4: ID-3 | B4: =_xlfn.XLOOKUP(A4,'Customer Names'!$A$2:$A$2336,'Customer Names'!$C$2:$C$2336,"Not Found") -> Phil | C4: =_xlfn.XLOOKUP(A4,'Medical Examine'!$A$2:$A$2336,'Medical Examine'!$B$2:$B$2336,"Not Found") -> 34.485 | D4: =_xlfn.XLOOKUP(A4,'Medical Examine'!$A$2:$A$2336,'Medical Examine'!$D$2:$D$2336,"Not Found") -> 11.87 | E4: =_xlfn.XLOOKUP(A4,'Medical Examine'!$A$2:$A$2336,'Medical Examine'!$E$2:$E$2336,"Not Found") -> YES | F4: =_xlfn.XLOOKUP(A4,'Medical Examine'!$A$2:$A$2336,'Medical Examine'!$F$2:$F$2336,"Not Found") -> NO | G4: =_xlfn.XLOOKUP(A4,'Medical Examine'!$A$2:$A$2336,'Medical Examine'!$G$2:$G$2336,"Not Found") -> NO | H4: =_xlfn.XLOOKUP(A4,'Medical Examine'!$A$2:$A$2336,'Medical Examine'!$H$2:$H$2336,"Not Found") -> 2 | I4: =_xlfn.XLOOKUP(A4,'Medical Examine'!$A$2:$A$2336,'Medical Examine'!$I$2:$I$2336,"Not Found") -> YES | J4: =_xlfn.XLOOKUP(A4,'Medical Examine'!$A$2:$A$2336,'Medical Examine'!$C$2:$C$2336,"Not Found") -> Obesity | K4: =IF(D4>=6.5,"Diabetic",IF(D4>=5.7,"Prediabetic","Normal")) -> Diabetic | L4: =_xlfn.XLOOKUP(A4,'Hospitalisation Details'!$A$2:$A$2344,'Hospitalisation Details'!$E$2:$E$2344,"") -> 25822 | M4: =_xlfn.XLOOKUP(A4,'Hospitalisation Details'!$A$2:$A$2344,'Hospitalisation Details'!$H$2:$H$2344,"") -> 60021.4 | N4: =_xlfn.XLOOKUP(A4,'Hospitalisation Details'!$A$2:$A$2344,'Hospitalisation Details'!$I$2:$I$2344,"") -> tier - 1 | O4: =_xlfn.XLOOKUP(A4,'Hospitalisation Details'!$A$2:$A$2344,'Hospitalisation Details'!$J$2:$J$2344,"") -> tier - 1 | P4: =_xlfn.XLOOKUP(A4,'Hospitalisation Details'!$A$2:$A$2344,'Hospitalisation Details'!$K$2:$K$2344,"") -> R1012 | Q4: =_xlfn.XLOOKUP(A4,'Hospitalisation Details'!$A$2:$A$2344,'Hospitalisation Details'!$F$2:$F$2344,"") -> 52
A5: ID-4 | B5: =_xlfn.XLOOKUP(A5,'Customer Names'!$A$2:$A$2336,'Customer Names'!$C$2:$C$2336,"Not Found") -> Kelsey | C5: =_xlfn.XLOOKUP(A5,'Medical Examine'!$A$2:$A$2336,'Medical Examine'!$B$2:$B$2336,"Not Found") -> 38.095 | D5: =_xlfn.XLOOKUP(A5,'Medical Examine'!$A$2:$A$2336,'Medical Examine'!$D$2:$D$2336,"Not Found") -> 6.05 | E5: =_xlfn.XLOOKUP(A5,'Medical Examine'!$A$2:$A$2336,'Medical Examine'!$E$2:$E$2336,"Not Found") -> NO | F5: =_xlfn.XLOOKUP(A5,'Medical Examine'!$A$2:$A$2336,'Medical Examine'!$F$2:$F$2336,"Not Found") -> NO | G5: =_xlfn.XLOOKUP(A5,'Medical Examine'!$A$2:$A$2336,'Medical Examine'!$G$2:$G$2336,"Not Found") -> NO | H5: =_xlfn.XLOOKUP(A5,'Medical Examine'!$A$2:$A$2336,'Medical Examine'!$H$2:$H$2336,"Not Found") -> 0 | I5: =_xlfn.XLOOKUP(A5,'Medical Examine'!$A$2:$A$2336,'Medical Examine'!$I$2:$I$2336,"Not Found") -> YES | J5: =_xlfn.XLOOKUP(A5,'Medical Examine'!$A$2:$A$2336,'Medical Examine'!$C$2:$C$2336,"Not Found") -> Obesity | K5: =IF(D5>=6.5,"Diabetic",IF(D5>=5.7,"Prediabetic","Normal")) -> Prediabetic | L5: =_xlfn.XLOOKUP(A5,'Hospitalisation Details'!$A$2:$A$2344,'Hospitalisation Details'!$E$2:$E$2344,"") -> 33395 | M5: =_xlfn.XLOOKUP(A5,'Hospitalisation Details'!$A$2:$A$2344,'Hospitalisation Details'!$H$2:$H$2344,"") -> 58571.07 | N5: =_xlfn.XLOOKUP(A5,'Hospitalisation Details'!$A$2:$A$2344,'Hospitalisation Details'!$I$2:$I$2344,"") -> tier - 1 | O5: =_xlfn.XLOOKUP(A5,'Hospitalisation Details'!$A$2:$A$2344,'Hospitalisation Details'!$J$2:$J$2344,"") -> tier - 3 | P5: =_xlfn.XLOOKUP(A5,'Hospitalisation Details'!$A$2:$A$2344,'Hospitalisation Details'!$K$2:$K$2344,"") -> R1024 | Q5: =_xlfn.XLOOKUP(A5,'Hospitalisation Details'!$A$2:$A$2344,'Hospitalisation Details'!$F$2:$F$2344,"") -> 32
A6: ID-5 | B6: =_xlfn.XLOOKUP(A6,'Customer Names'!$A$2:$A$2336,'Customer Names'!$C$2:$C$2336,"Not Found") -> Kristyn | C6: =_xlfn.XLOOKUP(A6,'Medical Examine'!$A$2:$A$2336,'Medical Examine'!$B$2:$B$2336,"Not Found") -> 35.53 | D6: =_xlfn.XLOOKUP(A6,'Medical Examine'!$A$2:$A$2336,'Medical Examine'!$D$2:$D$2336,"Not Found") -> 5.45 | E6: =_xlfn.XLOOKUP(A6,'Medical Examine'!$A$2:$A$2336,'Medical Examine'!$E$2:$E$2336,"Not Found") -> NO | F6: =_xlfn.XLOOKUP(A6,'Medical Examine'!$A$2:$A$2336,'Medical Examine'!$F$2:$F$2336,"Not Found") -> NO | G6: =_xlfn.XLOOKUP(A6,'Medical Examine'!$A$2:$A$2336,'Medical Examine'!$G$2:$G$2336,"Not Found") -> NO | H6: =_xlfn.XLOOKUP(A6,'Medical Examine'!$A$2:$A$2336,'Medical Examine'!$H$2:$H$2336,"Not Found") -> 0 | I6: =_xlfn.XLOOKUP(A6,'Medical Examine'!$A$2:$A$2336,'Medical Examine'!$I$2:$I$2336,"Not Found") -> YES | J6: =_xlfn.XLOOKUP(A6,'Medical Examine'!$A$2:$A$2336,'Medical Examine'!$C$2:$C$2336,"Not Found") -> Obesity | K6: =IF(D6>=6.5,"Diabetic",IF(D6>=5.7,"Prediabetic","Normal")) -> Normal | L6: =_xlfn.XLOOKUP(A6,'Hospitalisation Details'!$A$2:$A$2344,'Hospitalisation Details'!$E$2:$E$2344,"") -> 32678 | M6: =_xlfn.XLOOKUP(A6,'Hospitalisation Details'!$A$2:$A$2344,'Hospitalisation Details'!$H$2:$H$2344,"") -> 55135.4 | N6: =_xlfn.XLOOKUP(A6,'Hospitalisation Details'!$A$2:$A$2344,'Hospitalisation Details'!$I$2:$I$2344,"") -> tier - 1 | O6: =_xlfn.XLOOKUP(A6,'Hospitalisation Details'!$A$2:$A$2344,'Hospitalisation Details'!$J$2:$J$2344,"") -> tier - 2 | P6: =_xlfn.XLOOKUP(A6,'Hospitalisation Details'!$A$2:$A$2344,'Hospitalisation Details'!$K$2:$K$2344,"") -> R1012 | Q6: =_xlfn.XLOOKUP(A6,'Hospitalisation Details'!$A$2:$A$2344,'Hospitalisation Details'!$F$2:$F$2344,"") -> 33
A7: ID-6 | B7: =_xlfn.XLOOKUP(A7,'Customer Names'!$A$2:$A$2336,'Customer Names'!$C$2:$C$2336,"Not Found") -> Russell B. | C7: =_xlfn.XLOOKUP(A7,'Medical Examine'!$A$2:$A$2336,'Medical Examine'!$B$2:$B$2336,"Not Found") -> 32.8 | D7: =_xlfn.XLOOKUP(A7,'Medical Examine'!$A$2:$A$2336,'Medical Examine'!$D$2:$D$2336,"Not Found") -> 6.59 | E7: =_xlfn.XLOOKUP(A7,'Medical Examine'!$A$2:$A$2336,'Medical Examine'!$E$2:$E$2336,"Not Found") -> NO | F7: =_xlfn.XLOOKUP(A7,'Medical Examine'!$A$2:$A$2336,'Medical Examine'!$F$2:$F$2336,"Not Found") -> NO | G7: =_xlfn.XLOOKUP(A7,'Medical Examine'!$A$2:$A$2336,'Medical Examine'!$G$2:$G$2336,"Not Found") -> NO | H7: =_xlfn.XLOOKUP(A7,'Medical Examine'!$A$2:$A$2336,'Medical Examine'!$H$2:$H$2336,"Not Found") -> 0 | I7: =_xlfn.XLOOKUP(A7,'Medical Examine'!$A$2:$A$2336,'Medical Examine'!$I$2:$I$2336,"Not Found") -> YES | J7: =_xlfn.XLOOKUP(A7,'Medical Examine'!$A$2:$A$2336,'Medical Examine'!$C$2:$C$2336,"Not Found") -> Obesity | K7: =IF(D7>=6.5,"Diabetic",IF(D7>=5.7,"Prediabetic","Normal")) -> Diabetic | L7: =_xlfn.XLOOKUP(A7,'Hospitalisation Details'!$A$2:$A$2344,'Hospitalisation Details'!$E$2:$E$2344,"") -> 22862 | M7: =_xlfn.XLOOKUP(A7,'Hospitalisation Details'!$A$2:$A$2344,'Hospitalisation Details'!$H$2:$H$2344,"") -> 52590.83 | N7: =_xlfn.XLOOKUP(A7,'Hospitalisation Details'!$A$2:$A$2344,'Hospitalisation Details'!$I$2:$I$2344,"") -> tier - 1 | O7: =_xlfn.XLOOKUP(A7,'Hospitalisation Details'!$A$2:$A$2344,'Hospitalisation Details'!$J$2:$J$2344,"") -> tier - 3 | P7: =_xlfn.XLOOKUP(A7,'Hospitalisation Details'!$A$2:$A$2344,'Hospitalisation Details'!$K$2:$K$2344,"") -> R1011 | Q7: =_xlfn.XLOOKUP(A7,'Hospitalisation Details'!$A$2:$A$2344,'Hospitalisation Details'!$F$2:$F$2344,"") -> 60
A8: ID-7 | B8: =_xlfn.XLOOKUP(A8,'Customer Names'!$A$2:$A$2336,'Customer Names'!$C$2:$C$2336,"Not Found") -> Scott | C8: =_xlfn.XLOOKUP(A8,'Medical Examine'!$A$2:$A$2336,'Medical Examine'!$B$2:$B$2336,"Not Found") -> 36.4 | D8: =_xlfn.XLOOKUP(A8,'Medical Examine'!$A$2:$A$2336,'Medical Examine'!$D$2:$D$2336,"Not Found") -> 6.07 | E8: =_xlfn.XLOOKUP(A8,'Medical Examine'!$A$2:$A$2336,'Medical Examine'!$E$2:$E$2336,"Not Found") -> NO | F8: =_xlfn.XLOOKUP(A8,'Medical Examine'!$A$2:$A$2336,'Medical Examine'!$F$2:$F$2336,"Not Found") -> NO | G8: =_xlfn.XLOOKUP(A8,'Medical Examine'!$A$2:$A$2336,'Medical Examine'!$G$2:$G$2336,"Not Found") -> NO | H8: =_xlfn.XLOOKUP(A8,'Medical Examine'!$A$2:$A$2336,'Medical Examine'!$H$2:$H$2336,"Not Found") -> 0 | I8: =_xlfn.XLOOKUP(A8,'Medical Examine'!$A$2:$A$2336,'Medical Examine'!$I$2:$I$2336,"Not Found") -> YES | J8: =_xlfn.XLOOKUP(A8,'Medical Examine'!$A$2:$A$2336,'Medical Examine'!$C$2:$C$2336,"Not Found") -> Obesity | K8: =IF(D8>=6.5,"Diabetic",IF(D8>=5.7,"Prediabetic","Normal")) -> Prediabetic | L8: =_xlfn.XLOOKUP(A8,'Hospitalisation Details'!$A$2:$A$2344,'Hospitalisation Details'!$E$2:$E$2344,"") -> 34634 | M8: =_xlfn.XLOOKUP(A8,'Hospitalisation Details'!$A$2:$A$2344,'Hospitalisation Details'!$H$2:$H$2344,"") -> 51194.56 | N8: =_xlfn.XLOOKUP(A8,'Hospitalisation Details'!$A$2:$A$2344,'Hospitalisation Details'!$I$2:$I$2344,"") -> tier - 1 | O8: =_xlfn.XLOOKUP(A8,'Hospitalisation Details'!$A$2:$A$2344,'Hospitalisation Details'!$J$2:$J$2344,"") -> tier - 3 | P8: =_xlfn.XLOOKUP(A8,'Hospitalisation Details'!$A$2:$A$2344,'Hospitalisation Details'!$K$2:$K$2344,"") -> R1011 | Q8: =_xlfn.XLOOKUP(A8,'Hospitalisation Details'!$A$2:$A$2344,'Hospitalisation Details'!$F$2:$F$2344,"") -> 28
A9: ID-8 | B9: =_xlfn.XLOOKUP(A9,'Customer Names'!$A$2:$A$2336,'Customer Names'!$C$2:$C$2336,"Not Found") -> Stephen | C9: =_xlfn.XLOOKUP(A9,'Medical Examine'!$A$2:$A$2336,'Medical Examine'!$B$2:$B$2336,"Not Found") -> 36.96 | D9: =_xlfn.XLOOKUP(A9,'Medical Examine'!$A$2:$A$2336,'Medical Examine'!$D$2:$D$2336,"Not Found") -> 7.93 | E9: =_xlfn.XLOOKUP(A9,'Medical Examine'!$A$2:$A$2336,'Medical Examine'!$E$2:$E$2336,"Not Found") -> NO | F9: =_xlfn.XLOOKUP(A9,'Medical Examine'!$A$2:$A$2336,'Medical Examine'!$F$2:$F$2336,"Not Found") -> NO | G9: =_xlfn.XLOOKUP(A9,'Medical Examine'!$A$2:$A$2336,'Medical Examine'!$G$2:$G$2336,"Not Found") -> NO | H9: =_xlfn.XLOOKUP(A9,'Medical Examine'!$A$2:$A$2336,'Medical Examine'!$H$2:$H$2336,"Not Found") -> 3 | I9: =_xlfn.XLOOKUP(A9,'Medical Examine'!$A$2:$A$2336,'Medical Examine'!$I$2:$I$2336,"Not Found") -> YES | J9: =_xlfn.XLOOKUP(A9,'Medical Examine'!$A$2:$A$2336,'Medical Examine'!$C$2:$C$2336,"Not Found") -> Obesity | K9: =IF(D9>=6.5,"Diabetic",IF(D9>=5.7,"Prediabetic","Normal")) -> Diabetic | L9: =_xlfn.XLOOKUP(A9,'Hospitalisation Details'!$A$2:$A$2344,'Hospitalisation Details'!$E$2:$E$2344,"") -> 21363 | M9: =_xlfn.XLOOKUP(A9,'Hospitalisation Details'!$A$2:$A$2344,'Hospitalisation Details'!$H$2:$H$2344,"") -> 49577.66 | N9: =_xlfn.XLOOKUP(A9,'Hospitalisation Details'!$A$2:$A$2344,'Hospitalisation Details'!$I$2:$I$2344,"") -> tier - 2 | O9: =_xlfn.XLOOKUP(A9,'Hospitalisation Details'!$A$2:$A$2344,'Hospitalisation Details'!$J$2:$J$2344,"") -> tier - 2 | P9: =_xlfn.XLOOKUP(A9,'Hospitalisation Details'!$A$2:$A$2344,'Hospitalisation Details'!$K$2:$K$2344,"") -> R1013 | Q9: =_xlfn.XLOOKUP(A9,'Hospitalisation Details'!$A$2:$A$2344,'Hospitalisation Details'!$F$2:$F$2344,"") -> 64
A10: ID-9 | B10: =_xlfn.XLOOKUP(A10,'Customer Names'!$A$2:$A$2336,'Customer Names'!$C$2:$C$2336,"Not Found") -> Patrick R. | C10: =_xlfn.XLOOKUP(A10,'Medical Examine'!$A$2:$A$2336,'Medical Examine'!$B$2:$B$2336,"Not Found") -> 41.14 | D10: =_xlfn.XLOOKUP(A10,'Medical Examine'!$A$2:$A$2336,'Medical Examine'!$D$2:$D$2336,"Not Found") -> 9.58 | E10: =_xlfn.XLOOKUP(A10,'Medical Examine'!$A$2:$A$2336,'Medical Examine'!$E$2:$E$2336,"Not Found") -> YES | F10: =_xlfn.XLOOKUP(A10,'Medical Examine'!$A$2:$A$2336,'Medical Examine'!$F$2:$F$2336,"Not Found") -> NO | G10: =_xlfn.XLOOKUP(A10,'Medical Examine'!$A$2:$A$2336,'Medical Examine'!$G$2:$G$2336,"Not Found") -> YES | H10: =_xlfn.XLOOKUP(A10,'Medical Examine'!$A$2:$A$2336,'Medical Examine'!$H$2:$H$2336,"Not Found") -> 1 | I10: =_xlfn.XLOOKUP(A10,'Medical Examine'!$A$2:$A$2336,'Medical Examine'!$I$2:$I$2336,"Not Found") -> YES | J10: =_xlfn.XLOOKUP(A10,'Medical Examine'!$A$2:$A$2336,'Medical Examine'!$C$2:$C$2336,"Not Found") -> Obesity | K10: =IF(D10>=6.5,"Diabetic",IF(D10>=5.7,"Prediabetic","Normal")) -> Diabetic | L10: =_xlfn.XLOOKUP(A10,'Hospitalisation Details'!$A$2:$A$2344,'Hospitalisation Details'!$E$2:$E$2344,"") -> 23258 | M10: =_xlfn.XLOOKUP(A10,'Hospitalisation Details'!$A$2:$A$2344,'Hospitalisation Details'!$H$2:$H$2344,"") -> 48970.25 | N10: =_xlfn.XLOOKUP(A10,'Hospitalisation Details'!$A$2:$A$2344,'Hospitalisation Details'!$I$2:$I$2344,"") -> tier - 1 | O10: =_xlfn.XLOOKUP(A10,'Hospitalisation Details'!$A$2:$A$2344,'Hospitalisation Details'!$J$2:$J$2344,"") -> tier - 2 | P10: =_xlfn.XLOOKUP(A10,'Hospitalisation Details'!$A$2:$A$2344,'Hospitalisation Details'!$K$2:$K$2344,"") -> R1013 | Q10: =_xlfn.XLOOKUP(A10,'Hospitalisation Details'!$A$2:$A$2344,'Hospitalisation Details'!$F$2:$F$2344,"") -> 59
A11: ID-10 | B11: =_xlfn.XLOOKUP(A11,'Customer Names'!$A$2:$A$2336,'Customer Names'!$C$2:$C$2336,"Not Found") -> Brooke N. | C11: =_xlfn.XLOOKUP(A11,'Medical Examine'!$A$2:$A$2336,'Medical Examine'!$B$2:$B$2336,"Not Found") -> 38.06 | D11: =_xlfn.XLOOKUP(A11,'Medical Examine'!$A$2:$A$2336,'Medical Examine'!$D$2:$D$2336,"Not Found") -> 10.79 | E11: =_xlfn.XLOOKUP(A11,'Medical Examine'!$A$2:$A$2336,'Medical Examine'!$E$2:$E$2336,"Not Found") -> NO | F11: =_xlfn.XLOOKUP(A11,'Medical Examine'!$A$2:$A$2336,'Medical Examine'!$F$2:$F$2336,"Not Found") -> NO | G11: =_xlfn.XLOOKUP(A11,'Medical Examine'!$A$2:$A$2336,'Medical Examine'!$G$2:$G$2336,"Not Found") -> NO | H11: =_xlfn.XLOOKUP(A11,'Medical Examine'!$A$2:$A$2336,'Medical Examine'!$H$2:$H$2336,"Not Found") -> 0 | I11: =_xlfn.XLOOKUP(A11,'Medical Examine'!$A$2:$A$2336,'Medical Examine'!$I$2:$I$2336,"Not Found") -> YES | J11: =_xlfn.XLOOKUP(A11,'Medical Examine'!$A$2:$A$2336,'Medical Examine'!$C$2:$C$2336,"Not Found") -> Obesity | K11: =IF(D11>=6.5,"Diabetic",IF(D11>=5.7,"Prediabetic","Normal")) -> Diabetic | L11: =_xlfn.XLOOKUP(A11,'Hospitalisation Details'!$A$2:$A$2344,'Hospitalisation Details'!$E$2:$E$2344,"") -> 28853 | M11: =_xlfn.XLOOKUP(A11,'Hospitalisation Details'!$A$2:$A$2344,'Hospitalisation Details'!$H$2:$H$2344,"") -> 48885.14 | N11: =_xlfn.XLOOKUP(A11,'Hospitalisation Details'!$A$2:$A$2344,'Hospitalisation Details'!$I$2:$I$2344,"") -> tier - 1 | O11: =_xlfn.XLOOKUP(A11,'Hospitalisation Details'!$A$2:$A$2344,'Hospitalisation Details'!$J$2:$J$2344,"") -> tier - 2 | P11: =_xlfn.XLOOKUP(A11,'Hospitalisation Details'!$A$2:$A$2344,'Hospitalisation Details'!$K$2:$K$2344,"") -> R1013 | Q11: =_xlfn.XLOOKUP(A11,'Hospitalisation Details'!$A$2:$A$2344,'Hospitalisation Details'!$F$2:$F$2344,"") -> 44
A12: ID-11 | B12: =_xlfn.XLOOKUP(A12,'Customer Names'!$A$2:$A$2336,'Customer Names'!$C$2:$C$2336,"Not Found") -> Paola Andrea | C12: =_xlfn.XLOOKUP(A12,'Medical Examine'!$A$2:$A$2336,'Medical Examine'!$B$2:$B$2336,"Not Found") -> 37.7 | D12: =_xlfn.XLOOKUP(A12,'Medical Examine'!$A$2:$A$2336,'Medical Examine'!$D$2:$D$2336,"Not Found") -> 5.96 | E12: =_xlfn.XLOOKUP(A12,'Medical Examine'!$A$2:$A$2336,'Medical Examine'!$E$2:$E$2336,"Not Found") -> YES | F12: =_xlfn.XLOOKUP(A12,'Medical Examine'!$A$2:$A$2336,'Medical Examine'!$F$2:$F$2336,"Not Found") -> NO | G12: =_xlfn.XLOOKUP(A12,'Medical Examine'!$A$2:$A$2336,'Medical Examine'!$G$2:$G$2336,"Not Found") -> NO | H12: =_xlfn.XLOOKUP(A12,'Medical Examine'!$A$2:$A$2336,'Medical Examine'!$H$2:$H$2336,"Not Found") -> 2 | I12: =_xlfn.XLOOKUP(A12,'Medical Examine'!$A$2:$A$2336,'Medical Examine'!$I$2:$I$2336,"Not Found") -> YES | J12: =_xlfn.XLOOKUP(A12,'Medical Examine'!$A$2:$A$2336,'Medical Examine'!$C$2:$C$2336,"Not Found") -> Obesity | K12: =IF(D12>=6.5,"Diabetic",IF(D12>=5.7,"Prediabetic","Normal")) -> Prediabetic | L12: =_xlfn.XLOOKUP(A12,'Hospitalisation Details'!$A$2:$A$2344,'Hospitalisation Details'!$E$2:$E$2344,"") -> 21753 | M12: =_xlfn.XLOOKUP(A12,'Hospitalisation Details'!$A$2:$A$2344,'Hospitalisation Details'!$H$2:$H$2344,"") -> 48824.45 | N12: =_xlfn.XLOOKUP(A12,'Hospitalisation Details'!$A$2:$A$2344,'Hospitalisation Details'!$I$2:$I$2344,"") -> tier - 2 | O12: =_xlfn.XLOOKUP(A12,'Hospitalisation Details'!$A$2:$A$2344,'Hospitalisation Details'!$J$2:$J$2344,"") -> tier - 1 | P12: =_xlfn.XLOOKUP(A12,'Hospitalisation Details'!$A$2:$A$2344,'Hospitalisation Details'!$K$2:$K$2344,"") -> R1011 | Q12: =_xlfn.XLOOKUP(A12,'Hospitalisation Details'!$A$2:$A$2344,'Hospitalisation Details'!$F$2:$F$2344,"") -> 63
A13: ID-12 | B13: =_xlfn.XLOOKUP(A13,'Customer Names'!$A$2:$A$2336,'Customer Names'!$C$2:$C$2336,"Not Found") -> David | C13: =_xlfn.XLOOKUP(A13,'Medical Examine'!$A$2:$A$2336,'Medical Examine'!$B$2:$B$2336,"Not Found") -> 42.13 | D13: =_xlfn.XLOOKUP(A13,'Medical Examine'!$A$2:$A$2336,'Medical Examine'!$D$2:$D$2336,"Not Found") -> 11.9 | E13: =_xlfn.XLOOKUP(A13,'Medical Examine'!$A$2:$A$2336,'Medical Examine'!$E$2:$E$2336,"Not Found") -> NO | F13: =_xlfn.XLOOKUP(A13,'Medical Examine'!$A$2:$A$2336,'Medical Examine'!$F$2:$F$2336,"Not Found") -> NO | G13: =_xlfn.XLOOKUP(A13,'Medical Examine'!$A$2:$A$2336,'Medical Examine'!$G$2:$G$2336,"Not Found") -> NO | H13: =_xlfn.XLOOKUP(A13,'Medical Examine'!$A$2:$A$2336,'Medical Examine'!$H$2:$H$2336,"Not Found") -> 0 | I13: =_xlfn.XLOOKUP(A13,'Medical Examine'!$A$2:$A$2336,'Medical Examine'!$I$2:$I$2336,"Not Found") -> YES | J13: =_xlfn.XLOOKUP(A13,'Medical Examine'!$A$2:$A$2336,'Medical Examine'!$C$2:$C$2336,"Not Found") -> Obesity | K13: =IF(D13>=6.5,"Diabetic",IF(D13>=5.7,"Prediabetic","Normal")) -> Diabetic | L13: =_xlfn.XLOOKUP(A13,'Hospitalisation Details'!$A$2:$A$2344,'Hospitalisation Details'!$E$2:$E$2344,"") -> 24042 | M13: =_xlfn.XLOOKUP(A13,'Hospitalisation Details'!$A$2:$A$2344,'Hospitalisation Details'!$H$2:$H$2344,"") -> 48675.52 | N13: =_xlfn.XLOOKUP(A13,'Hospitalisation Details'!$A$2:$A$2344,'Hospitalisation Details'!$I$2:$I$2344,"") -> tier - 1 | O13: =_xlfn.XLOOKUP(A13,'Hospitalisation Details'!$A$2:$A$2344,'Hospitalisation Details'!$J$2:$J$2344,"") -> tier - 2 | P13: =_xlfn.XLOOKUP(A13,'Hospitalisation Details'!$A$2:$A$2344,'Hospitalisation Details'!$K$2:$K$2344,"") -> R1013 | Q13: =_xlfn.XLOOKUP(A13,'Hospitalisation Details'!$A$2:$A$2344,'Hospitalisation Details'!$F$2:$F$2344,"") -> 57
... A2325: ID-2324 | B2325: =_xlfn.XLOOKUP(A2325,'Customer Names'!$A$2:$A$2336,'Customer Names'!$C$2:$C$2336,"Not Found") -> Meghan K | C2325: =_xlfn.XLOOKUP(A2325,'Medical Examine'!$A$2:$A$2336,'Medical Examine'!$B$2:$B$2336,"Not Found") -> 22.24 | D2325: =_xlfn.XLOOKUP(A2325,'Medical Examine'!$A$2:$A$2336,'Medical Examine'!$D$2:$D$2336,"Not Found") -> 5.04 | E2325: =_xlfn.XLOOKUP(A2325,'Medical Examine'!$A$2:$A$2336,'Medical Examine'!$E$2:$E$2336,"Not Found") -> NO | F2325: =_xlfn.XLOOKUP(A2325,'Medical Examine'!$A$2:$A$2336,'Medical Examine'!$F$2:$F$2336,"Not Found") -> NO | G2325: =_xlfn.XLOOKUP(A2325,'Medical Examine'!$A$2:$A$2336,'Medical Examine'!$G$2:$G$2336,"Not Found") -> NO | H2325: =_xlfn.XLOOKUP(A2325,'Medical Examine'!$A$2:$A$2336,'Medical Examine'!$H$2:$H$2336,"Not Found") -> 0 | I2325: =_xlfn.XLOOKUP(A2325,'Medical Examine'!$A$2:$A$2336,'Medical Examine'!$I$2:$I$2336,"Not Found") -> NO | J2325: =_xlfn.XLOOKUP(A2325,'Medical Examine'!$A$2:$A$2336,'Medical Examine'!$C$2:$C$2336,"Not Found") -> Normal Weight | K2325: =IF(D2325>=6.5,"Diabetic",IF(D2325>=5.7,"Prediabetic","Normal")) -> Normal | L2325: =_xlfn.XLOOKUP(A2325,'Hospitalisation Details'!$A$2:$A$2344,'Hospitalisation Details'!$E$2:$E$2344,"") -> 36520 | M2325: =_xlfn.XLOOKUP(A2325,'Hospitalisation Details'!$A$2:$A$2344,'Hospitalisation Details'!$H$2:$H$2344,"") -> 700 | N2325: =_xlfn.XLOOKUP(A2325,'Hospitalisation Details'!$A$2:$A$2344,'Hospitalisation Details'!$I$2:$I$2344,"") -> tier - 2 | O2325: =_xlfn.XLOOKUP(A2325,'Hospitalisation Details'!$A$2:$A$2344,'Hospitalisation Details'!$J$2:$J$2344,"") -> tier - 3 | P2325: =_xlfn.XLOOKUP(A2325,'Hospitalisation Details'!$A$2:$A$2344,'Hospitalisation Details'!$K$2:$K$2344,"") -> R1013 | Q2325: =_xlfn.XLOOKUP(A2325,'Hospitalisation Details'!$A$2:$A$2344,'Hospitalisation Details'!$F$2:$F$2344,"") -> 23
A2326: ID-2325 | B2326: =_xlfn.XLOOKUP(A2326,'Customer Names'!$A$2:$A$2336,'Customer Names'!$C$2:$C$2336,"Not Found") -> Fred | C2326: =_xlfn.XLOOKUP(A2326,'Medical Examine'!$A$2:$A$2336,'Medical Examine'!$B$2:$B$2336,"Not Found") -> 24.76 | D2326: 3 | E2326: =_xlfn.XLOOKUP(A2326,'Medical Examine'!$A$2:$A$2336,'Medical Examine'!$E$2:$E$2336,"Not Found") -> YES | F2326: =_xlfn.XLOOKUP(A2326,'Medical Examine'!$A$2:$A$2336,'Medical Examine'!$F$2:$F$2336,"Not Found") -> NO | G2326: =_xlfn.XLOOKUP(A2326,'Medical Examine'!$A$2:$A$2336,'Medical Examine'!$G$2:$G$2336,"Not Found") -> NO | H2326: =_xlfn.XLOOKUP(A2326,'Medical Examine'!$A$2:$A$2336,'Medical Examine'!$H$2:$H$2336,"Not Found") -> 0 | I2326: =_xlfn.XLOOKUP(A2326,'Medical Examine'!$A$2:$A$2336,'Medical Examine'!$I$2:$I$2336,"Not Found") -> NO | J2326: =_xlfn.XLOOKUP(A2326,'Medical Examine'!$A$2:$A$2336,'Medical Examine'!$C$2:$C$2336,"Not Found") -> Normal Weight | K2326: =IF(D2326>=6.5,"Diabetic",IF(D2326>=5.7,"Prediabetic","Normal")) -> Normal | L2326: =_xlfn.XLOOKUP(A2326,'Hospitalisation Details'!$A$2:$A$2344,'Hospitalisation Details'!$E$2:$E$2344,"") -> 37146 | M2326: =_xlfn.XLOOKUP(A2326,'Hospitalisation Details'!$A$2:$A$2344,'Hospitalisation Details'!$H$2:$H$2344,"") -> 687.54 | N2326: =_xlfn.XLOOKUP(A2326,'Hospitalisation Details'!$A$2:$A$2344,'Hospitalisation Details'!$I$2:$I$2344,"") -> tier - 3 | O2326: =_xlfn.XLOOKUP(A2326,'Hospitalisation Details'!$A$2:$A$2344,'Hospitalisation Details'!$J$2:$J$2344,"") -> tier - 2 | P2326: =_xlfn.XLOOKUP(A2326,'Hospitalisation Details'!$A$2:$A$2344,'Hospitalisation Details'!$K$2:$K$2344,"") -> R1013 | Q2326: =_xlfn.XLOOKUP(A2326,'Hospitalisation Details'!$A$2:$A$2344,'Hospitalisation Details'!$F$2:$F$2344,"") -> 21
A2327: ID-2326 | B2327: =_xlfn.XLOOKUP(A2327,'Customer Names'!$A$2:$A$2336,'Customer Names'!$C$2:$C$2336,"Not Found") -> Sebastian | C2327: =_xlfn.XLOOKUP(A2327,'Medical Examine'!$A$2:$A$2336,'Medical Examine'!$B$2:$B$2336,"Not Found") -> 20.1 | D2327: =_xlfn.XLOOKUP(A2327,'Medical Examine'!$A$2:$A$2336,'Medical Examine'!$D$2:$D$2336,"Not Found") -> 5.6 | E2327: =_xlfn.XLOOKUP(A2327,'Medical Examine'!$A$2:$A$2336,'Medical Examine'!$E$2:$E$2336,"Not Found") -> YES | F2327: =_xlfn.XLOOKUP(A2327,'Medical Examine'!$A$2:$A$2336,'Medical Examine'!$F$2:$F$2336,"Not Found") -> NO | G2327: =_xlfn.XLOOKUP(A2327,'Medical Examine'!$A$2:$A$2336,'Medical Examine'!$G$2:$G$2336,"Not Found") -> YES | H2327: =_xlfn.XLOOKUP(A2327,'Medical Examine'!$A$2:$A$2336,'Medical Examine'!$H$2:$H$2336,"Not Found") -> 1 | I2327: =_xlfn.XLOOKUP(A2327,'Medical Examine'!$A$2:$A$2336,'Medical Examine'!$I$2:$I$2336,"Not Found") -> NO | J2327: =_xlfn.XLOOKUP(A2327,'Medical Examine'!$A$2:$A$2336,'Medical Examine'!$C$2:$C$2336,"Not Found") -> Normal Weight | K2327: =IF(D2327>=6.5,"Diabetic",IF(D2327>=5.7,"Prediabetic","Normal")) -> Normal | L2327: =_xlfn.XLOOKUP(A2327,'Hospitalisation Details'!$A$2:$A$2344,'Hospitalisation Details'!$E$2:$E$2344,"") -> 35743 | M2327: =_xlfn.XLOOKUP(A2327,'Hospitalisation Details'!$A$2:$A$2344,'Hospitalisation Details'!$H$2:$H$2344,"") -> 670 | N2327: =_xlfn.XLOOKUP(A2327,'Hospitalisation Details'!$A$2:$A$2344,'Hospitalisation Details'!$I$2:$I$2344,"") -> tier - 3 | O2327: =_xlfn.XLOOKUP(A2327,'Hospitalisation Details'!$A$2:$A$2344,'Hospitalisation Details'!$J$2:$J$2344,"") -> tier - 3 | P2327: =_xlfn.XLOOKUP(A2327,'Hospitalisation Details'!$A$2:$A$2344,'Hospitalisation Details'!$K$2:$K$2344,"") -> R1013 | Q2327: =_xlfn.XLOOKUP(A2327,'Hospitalisation Details'!$A$2:$A$2344,'Hospitalisation Details'!$F$2:$F$2344,"") -> 25
A2328: ID-2327 | B2328: =_xlfn.XLOOKUP(A2328,'Customer Names'!$A$2:$A$2336,'Customer Names'!$C$2:$C$2336,"Not Found") -> Laura | C2328: =_xlfn.XLOOKUP(A2328,'Medical Examine'!$A$2:$A$2336,'Medical Examine'!$B$2:$B$2336,"Not Found") -> 21.77 | D2328: =_xlfn.XLOOKUP(A2328,'Medical Examine'!$A$2:$A$2336,'Medical Examine'!$D$2:$D$2336,"Not Found") -> 10.67 | E2328: =_xlfn.XLOOKUP(A2328,'Medical Examine'!$A$2:$A$2336,'Medical Examine'!$E$2:$E$2336,"Not Found") -> NO | F2328: =_xlfn.XLOOKUP(A2328,'Medical Examine'!$A$2:$A$2336,'Medical Examine'!$F$2:$F$2336,"Not Found") -> NO | G2328: =_xlfn.XLOOKUP(A2328,'Medical Examine'!$A$2:$A$2336,'Medical Examine'!$G$2:$G$2336,"Not Found") -> NO | H2328: =_xlfn.XLOOKUP(A2328,'Medical Examine'!$A$2:$A$2336,'Medical Examine'!$H$2:$H$2336,"Not Found") -> 0 | I2328: =_xlfn.XLOOKUP(A2328,'Medical Examine'!$A$2:$A$2336,'Medical Examine'!$I$2:$I$2336,"Not Found") -> NO | J2328: =_xlfn.XLOOKUP(A2328,'Medical Examine'!$A$2:$A$2336,'Medical Examine'!$C$2:$C$2336,"Not Found") -> Normal Weight | K2328: =IF(D2328>=6.5,"Diabetic",IF(D2328>=5.7,"Prediabetic","Normal")) -> Diabetic | L2328: =_xlfn.XLOOKUP(A2328,'Hospitalisation Details'!$A$2:$A$2344,'Hospitalisation Details'!$E$2:$E$2344,"") -> 37589 | M2328: =_xlfn.XLOOKUP(A2328,'Hospitalisation Details'!$A$2:$A$2344,'Hospitalisation Details'!$H$2:$H$2344,"") -> 668 | N2328: =_xlfn.XLOOKUP(A2328,'Hospitalisation Details'!$A$2:$A$2344,'Hospitalisation Details'!$I$2:$I$2344,"") -> tier - 3 | O2328: =_xlfn.XLOOKUP(A2328,'Hospitalisation Details'!$A$2:$A$2344,'Hospitalisation Details'!$J$2:$J$2344,"") -> tier - 2 | P2328: =_xlfn.XLOOKUP(A2328,'Hospitalisation Details'!$A$2:$A$2344,'Hospitalisation Details'!$K$2:$K$2344,"") -> R1012 | Q2328: =_xlfn.XLOOKUP(A2328,'Hospitalisation Details'!$A$2:$A$2344,'Hospitalisation Details'!$F$2:$F$2344,"") -> 20
A2329: ID-2328 | B2329: =_xlfn.XLOOKUP(A2329,'Customer Names'!$A$2:$A$2336,'Customer Names'!$C$2:$C$2336,"Not Found") -> Nicole | C2329: =_xlfn.XLOOKUP(A2329,'Medical Examine'!$A$2:$A$2336,'Medical Examine'!$B$2:$B$2336,"Not Found") -> 17.82 | D2329: =_xlfn.XLOOKUP(A2329,'Medical Examine'!$A$2:$A$2336,'Medical Examine'!$D$2:$D$2336,"Not Found") -> 5.26 | E2329: =_xlfn.XLOOKUP(A2329,'Medical Examine'!$A$2:$A$2336,'Medical Examine'!$E$2:$E$2336,"Not Found") -> YES | F2329: =_xlfn.XLOOKUP(A2329,'Medical Examine'!$A$2:$A$2336,'Medical Examine'!$F$2:$F$2336,"Not Found") -> NO | G2329: =_xlfn.XLOOKUP(A2329,'Medical Examine'!$A$2:$A$2336,'Medical Examine'!$G$2:$G$2336,"Not Found") -> NO | H2329: =_xlfn.XLOOKUP(A2329,'Medical Examine'!$A$2:$A$2336,'Medical Examine'!$H$2:$H$2336,"Not Found") -> 1 | I2329: =_xlfn.XLOOKUP(A2329,'Medical Examine'!$A$2:$A$2336,'Medical Examine'!$I$2:$I$2336,"Not Found") -> NO | J2329: =_xlfn.XLOOKUP(A2329,'Medical Examine'!$A$2:$A$2336,'Medical Examine'!$C$2:$C$2336,"Not Found") -> Under Weight | K2329: =IF(D2329>=6.5,"Diabetic",IF(D2329>=5.7,"Prediabetic","Normal")) -> Normal | L2329: =_xlfn.XLOOKUP(A2329,'Hospitalisation Details'!$A$2:$A$2344,'Hospitalisation Details'!$E$2:$E$2344,"") -> 34884 | M2329: =_xlfn.XLOOKUP(A2329,'Hospitalisation Details'!$A$2:$A$2344,'Hospitalisation Details'!$H$2:$H$2344,"") -> 650 | N2329: =_xlfn.XLOOKUP(A2329,'Hospitalisation Details'!$A$2:$A$2344,'Hospitalisation Details'!$I$2:$I$2344,"") -> tier - 3 | O2329: =_xlfn.XLOOKUP(A2329,'Hospitalisation Details'!$A$2:$A$2344,'Hospitalisation Details'!$J$2:$J$2344,"") -> tier - 3 | P2329: =_xlfn.XLOOKUP(A2329,'Hospitalisation Details'!$A$2:$A$2344,'Hospitalisation Details'!$K$2:$K$2344,"") -> R1013 | Q2329: =_xlfn.XLOOKUP(A2329,'Hospitalisation Details'!$A$2:$A$2344,'Hospitalisation Details'!$F$2:$F$2344,"") -> 27
A2330: ID-2329 | B2330: =_xlfn.XLOOKUP(A2330,'Customer Names'!$A$2:$A$2336,'Customer Names'!$C$2:$C$2336,"Not Found") -> Susan E | C2330: =_xlfn.XLOOKUP(A2330,'Medical Examine'!$A$2:$A$2336,'Medical Examine'!$B$2:$B$2336,"Not Found") -> 17.07 | D2330: =_xlfn.XLOOKUP(A2330,'Medical Examine'!$A$2:$A$2336,'Medical Examine'!$D$2:$D$2336,"Not Found") -> 5.22 | E2330: =_xlfn.XLOOKUP(A2330,'Medical Examine'!$A$2:$A$2336,'Medical Examine'!$E$2:$E$2336,"Not Found") -> NO | F2330: =_xlfn.XLOOKUP(A2330,'Medical Examine'!$A$2:$A$2336,'Medical Examine'!$F$2:$F$2336,"Not Found") -> NO | G2330: =_xlfn.XLOOKUP(A2330,'Medical Examine'!$A$2:$A$2336,'Medical Examine'!$G$2:$G$2336,"Not Found") -> YES | H2330: =_xlfn.XLOOKUP(A2330,'Medical Examine'!$A$2:$A$2336,'Medical Examine'!$H$2:$H$2336,"Not Found") -> 1 | I2330: =_xlfn.XLOOKUP(A2330,'Medical Examine'!$A$2:$A$2336,'Medical Examine'!$I$2:$I$2336,"Not Found") -> NO | J2330: =_xlfn.XLOOKUP(A2330,'Medical Examine'!$A$2:$A$2336,'Medical Examine'!$C$2:$C$2336,"Not Found") -> Under Weight | K2330: =IF(D2330>=6.5,"Diabetic",IF(D2330>=5.7,"Prediabetic","Normal")) -> Normal | L2330: =_xlfn.XLOOKUP(A2330,'Hospitalisation Details'!$A$2:$A$2344,'Hospitalisation Details'!$E$2:$E$2344,"") -> 34121 | M2330: =_xlfn.XLOOKUP(A2330,'Hospitalisation Details'!$A$2:$A$2344,'Hospitalisation Details'!$H$2:$H$2344,"") -> 650 | N2330: =_xlfn.XLOOKUP(A2330,'Hospitalisation Details'!$A$2:$A$2344,'Hospitalisation Details'!$I$2:$I$2344,"") -> tier - 3 | O2330: =_xlfn.XLOOKUP(A2330,'Hospitalisation Details'!$A$2:$A$2344,'Hospitalisation Details'!$J$2:$J$2344,"") -> tier - 3 | P2330: =_xlfn.XLOOKUP(A2330,'Hospitalisation Details'!$A$2:$A$2344,'Hospitalisation Details'!$K$2:$K$2344,"") -> R1013 | Q2330: =_xlfn.XLOOKUP(A2330,'Hospitalisation Details'!$A$2:$A$2344,'Hospitalisation Details'!$F$2:$F$2344,"") -> 30
A2331: ID-2330 | B2331: =_xlfn.XLOOKUP(A2331,'Customer Names'!$A$2:$A$2336,'Customer Names'!$C$2:$C$2336,"Not Found") -> Katy | C2331: =_xlfn.XLOOKUP(A2331,'Medical Examine'!$A$2:$A$2336,'Medical Examine'!$B$2:$B$2336,"Not Found") -> 22.24 | D2331: =_xlfn.XLOOKUP(A2331,'Medical Examine'!$A$2:$A$2336,'Medical Examine'!$D$2:$D$2336,"Not Found") -> 4.29 | E2331: =_xlfn.XLOOKUP(A2331,'Medical Examine'!$A$2:$A$2336,'Medical Examine'!$E$2:$E$2336,"Not Found") -> YES | F2331: =_xlfn.XLOOKUP(A2331,'Medical Examine'!$A$2:$A$2336,'Medical Examine'!$F$2:$F$2336,"Not Found") -> NO | G2331: =_xlfn.XLOOKUP(A2331,'Medical Examine'!$A$2:$A$2336,'Medical Examine'!$G$2:$G$2336,"Not Found") -> NO | H2331: =_xlfn.XLOOKUP(A2331,'Medical Examine'!$A$2:$A$2336,'Medical Examine'!$H$2:$H$2336,"Not Found") -> 0 | I2331: =_xlfn.XLOOKUP(A2331,'Medical Examine'!$A$2:$A$2336,'Medical Examine'!$I$2:$I$2336,"Not Found") -> NO | J2331: =_xlfn.XLOOKUP(A2331,'Medical Examine'!$A$2:$A$2336,'Medical Examine'!$C$2:$C$2336,"Not Found") -> Normal Weight | K2331: =IF(D2331>=6.5,"Diabetic",IF(D2331>=5.7,"Prediabetic","Normal")) -> Normal | L2331: =_xlfn.XLOOKUP(A2331,'Hospitalisation Details'!$A$2:$A$2344,'Hospitalisation Details'!$E$2:$E$2344,"") -> 37215 | M2331: =_xlfn.XLOOKUP(A2331,'Hospitalisation Details'!$A$2:$A$2344,'Hospitalisation Details'!$H$2:$H$2344,"") -> 646.14 | N2331: =_xlfn.XLOOKUP(A2331,'Hospitalisation Details'!$A$2:$A$2344,'Hospitalisation Details'!$I$2:$I$2344,"") -> tier - 3 | O2331: =_xlfn.XLOOKUP(A2331,'Hospitalisation Details'!$A$2:$A$2344,'Hospitalisation Details'!$J$2:$J$2344,"") -> tier - 3 | P2331: =_xlfn.XLOOKUP(A2331,'Hospitalisation Details'!$A$2:$A$2344,'Hospitalisation Details'!$K$2:$K$2344,"") -> R1012 | Q2331: =_xlfn.XLOOKUP(A2331,'Hospitalisation Details'!$A$2:$A$2344,'Hospitalisation Details'!$F$2:$F$2344,"") -> 21
A2332: ID-2331 | B2332: =_xlfn.XLOOKUP(A2332,'Customer Names'!$A$2:$A$2336,'Customer Names'!$C$2:$C$2336,"Not Found") -> Jordan | C2332: =_xlfn.XLOOKUP(A2332,'Medical Examine'!$A$2:$A$2336,'Medical Examine'!$B$2:$B$2336,"Not Found") -> 22.34 | D2332: =_xlfn.XLOOKUP(A2332,'Medical Examine'!$A$2:$A$2336,'Medical Examine'!$D$2:$D$2336,"Not Found") -> 5.57 | E2332: =_xlfn.XLOOKUP(A2332,'Medical Examine'!$A$2:$A$2336,'Medical Examine'!$E$2:$E$2336,"Not Found") -> NO | F2332: =_xlfn.XLOOKUP(A2332,'Medical Examine'!$A$2:$A$2336,'Medical Examine'!$F$2:$F$2336,"Not Found") -> NO | G2332: =_xlfn.XLOOKUP(A2332,'Medical Examine'!$A$2:$A$2336,'Medical Examine'!$G$2:$G$2336,"Not Found") -> NO | H2332: =_xlfn.XLOOKUP(A2332,'Medical Examine'!$A$2:$A$2336,'Medical Examine'!$H$2:$H$2336,"Not Found") -> 1 | I2332: =_xlfn.XLOOKUP(A2332,'Medical Examine'!$A$2:$A$2336,'Medical Examine'!$I$2:$I$2336,"Not Found") -> NO | J2332: Normal Weight | K2332: =IF(D2332>=6.5,"Diabetic",IF(D2332>=5.7,"Prediabetic","Normal")) -> Normal | L2332: =_xlfn.XLOOKUP(A2332,'Hospitalisation Details'!$A$2:$A$2344,'Hospitalisation Details'!$E$2:$E$2344,"") -> 36003 | M2332: =_xlfn.XLOOKUP(A2332,'Hospitalisation Details'!$A$2:$A$2344,'Hospitalisation Details'!$H$2:$H$2344,"") -> 637.26 | N2332: =_xlfn.XLOOKUP(A2332,'Hospitalisation Details'!$A$2:$A$2344,'Hospitalisation Details'!$I$2:$I$2344,"") -> tier - 3 | O2332: =_xlfn.XLOOKUP(A2332,'Hospitalisation Details'!$A$2:$A$2344,'Hospitalisation Details'!$J$2:$J$2344,"") -> tier - 3 | P2332: =_xlfn.XLOOKUP(A2332,'Hospitalisation Details'!$A$2:$A$2344,'Hospitalisation Details'!$K$2:$K$2344,"") -> R1013 | Q2332: =_xlfn.XLOOKUP(A2332,'Hospitalisation Details'!$A$2:$A$2344,'Hospitalisation Details'!$F$2:$F$2344,"") -> 24
